[2024-03-05T08:05:03.970+0000] {taskinstance.py:1979} INFO - Dependencies all met for dep_context=non-requeueable deps ti=<TaskInstance: test_dag_v2.second_task manual__2024-03-05T08:03:01.103675+00:00 [queued]>
[2024-03-05T08:05:03.976+0000] {taskinstance.py:1979} INFO - Dependencies all met for dep_context=requeueable deps ti=<TaskInstance: test_dag_v2.second_task manual__2024-03-05T08:03:01.103675+00:00 [queued]>
[2024-03-05T08:05:03.977+0000] {taskinstance.py:2193} INFO - Starting attempt 2 of 6
[2024-03-05T08:05:03.987+0000] {taskinstance.py:2214} INFO - Executing <Task(BashOperator): second_task> on 2024-03-05 08:03:01.103675+00:00
[2024-03-05T08:05:03.990+0000] {standard_task_runner.py:60} INFO - Started process 947 to run task
[2024-03-05T08:05:03.992+0000] {standard_task_runner.py:87} INFO - Running: ['***', 'tasks', 'run', 'test_dag_v2', 'second_task', 'manual__2024-03-05T08:03:01.103675+00:00', '--job-id', '10', '--raw', '--subdir', 'DAGS_FOLDER/test_dag.py', '--cfg-path', '/tmp/tmpixeu7xmg']
[2024-03-05T08:05:03.994+0000] {standard_task_runner.py:88} INFO - Job 10: Subtask second_task
[2024-03-05T08:05:04.023+0000] {task_command.py:423} INFO - Running <TaskInstance: test_dag_v2.second_task manual__2024-03-05T08:03:01.103675+00:00 [running]> on host a94d9406bb00
[2024-03-05T08:05:04.163+0000] {taskinstance.py:2510} INFO - Exporting env vars: AIRFLOW_CTX_DAG_OWNER='minh' AIRFLOW_CTX_DAG_ID='test_dag_v2' AIRFLOW_CTX_TASK_ID='second_task' AIRFLOW_CTX_EXECUTION_DATE='2024-03-05T08:03:01.103675+00:00' AIRFLOW_CTX_TRY_NUMBER='2' AIRFLOW_CTX_DAG_RUN_ID='manual__2024-03-05T08:03:01.103675+00:00'
[2024-03-05T08:05:04.164+0000] {subprocess.py:63} INFO - Tmp dir root location: /tmp
[2024-03-05T08:05:04.165+0000] {subprocess.py:75} INFO - Running command: ['/usr/bin/bash', '-c', 'echo, this is the second task']
[2024-03-05T08:05:04.169+0000] {subprocess.py:86} INFO - Output:
[2024-03-05T08:05:04.170+0000] {subprocess.py:93} INFO - /usr/bin/bash: line 1: echo,: command not found
[2024-03-05T08:05:04.171+0000] {subprocess.py:97} INFO - Command exited with return code 127
[2024-03-05T08:05:04.178+0000] {taskinstance.py:2728} ERROR - Task failed with exception
Traceback (most recent call last):
  File "/home/airflow/.local/lib/python3.11/site-packages/airflow/models/taskinstance.py", line 444, in _execute_task
    result = _execute_callable(context=context, **execute_callable_kwargs)
             ^^^^^^^^^^^^^^^^^^^^^^^^^^^^^^^^^^^^^^^^^^^^^^^^^^^^^^^^^^^^^
  File "/home/airflow/.local/lib/python3.11/site-packages/airflow/models/taskinstance.py", line 414, in _execute_callable
    return execute_callable(context=context, **execute_callable_kwargs)
           ^^^^^^^^^^^^^^^^^^^^^^^^^^^^^^^^^^^^^^^^^^^^^^^^^^^^^^^^^^^^
  File "/home/airflow/.local/lib/python3.11/site-packages/airflow/operators/bash.py", line 212, in execute
    raise AirflowException(
airflow.exceptions.AirflowException: Bash command failed. The command returned a non-zero exit code 127.
[2024-03-05T08:05:04.180+0000] {taskinstance.py:1149} INFO - Marking task as UP_FOR_RETRY. dag_id=test_dag_v2, task_id=second_task, execution_date=20240305T080301, start_date=20240305T080503, end_date=20240305T080504
[2024-03-05T08:05:04.188+0000] {standard_task_runner.py:107} ERROR - Failed to execute job 10 for task second_task (Bash command failed. The command returned a non-zero exit code 127.; 947)
[2024-03-05T08:05:04.222+0000] {local_task_job_runner.py:234} INFO - Task exited with return code 1
[2024-03-05T08:05:04.233+0000] {taskinstance.py:3309} INFO - 0 downstream tasks scheduled from follow-on schedule check
