[2024-03-05T08:01:37.680+0000] {taskinstance.py:1979} INFO - Dependencies all met for dep_context=non-requeueable deps ti=<TaskInstance: test_dag.second_task manual__2024-03-05T08:01:35.725029+00:00 [queued]>
[2024-03-05T08:01:37.685+0000] {taskinstance.py:1979} INFO - Dependencies all met for dep_context=requeueable deps ti=<TaskInstance: test_dag.second_task manual__2024-03-05T08:01:35.725029+00:00 [queued]>
[2024-03-05T08:01:37.685+0000] {taskinstance.py:2193} INFO - Starting attempt 1 of 6
[2024-03-05T08:01:37.692+0000] {taskinstance.py:2214} INFO - Executing <Task(BashOperator): second_task> on 2024-03-05 08:01:35.725029+00:00
[2024-03-05T08:01:37.695+0000] {standard_task_runner.py:60} INFO - Started process 852 to run task
[2024-03-05T08:01:37.698+0000] {standard_task_runner.py:87} INFO - Running: ['***', 'tasks', 'run', 'test_dag', 'second_task', 'manual__2024-03-05T08:01:35.725029+00:00', '--job-id', '5', '--raw', '--subdir', 'DAGS_FOLDER/test_dag.py', '--cfg-path', '/tmp/tmp5j80chrh']
[2024-03-05T08:01:37.699+0000] {standard_task_runner.py:88} INFO - Job 5: Subtask second_task
[2024-03-05T08:01:37.726+0000] {task_command.py:423} INFO - Running <TaskInstance: test_dag.second_task manual__2024-03-05T08:01:35.725029+00:00 [running]> on host a94d9406bb00
[2024-03-05T08:01:37.868+0000] {taskinstance.py:2510} INFO - Exporting env vars: AIRFLOW_CTX_DAG_OWNER='minh' AIRFLOW_CTX_DAG_ID='test_dag' AIRFLOW_CTX_TASK_ID='second_task' AIRFLOW_CTX_EXECUTION_DATE='2024-03-05T08:01:35.725029+00:00' AIRFLOW_CTX_TRY_NUMBER='1' AIRFLOW_CTX_DAG_RUN_ID='manual__2024-03-05T08:01:35.725029+00:00'
[2024-03-05T08:01:37.869+0000] {subprocess.py:63} INFO - Tmp dir root location: /tmp
[2024-03-05T08:01:37.870+0000] {subprocess.py:75} INFO - Running command: ['/usr/bin/bash', '-c', 'echo, this is the second task']
[2024-03-05T08:01:37.874+0000] {subprocess.py:86} INFO - Output:
[2024-03-05T08:01:37.876+0000] {subprocess.py:93} INFO - /usr/bin/bash: line 1: echo,: command not found
[2024-03-05T08:01:37.876+0000] {subprocess.py:97} INFO - Command exited with return code 127
[2024-03-05T08:01:37.884+0000] {taskinstance.py:2728} ERROR - Task failed with exception
Traceback (most recent call last):
  File "/home/airflow/.local/lib/python3.11/site-packages/airflow/models/taskinstance.py", line 444, in _execute_task
    result = _execute_callable(context=context, **execute_callable_kwargs)
             ^^^^^^^^^^^^^^^^^^^^^^^^^^^^^^^^^^^^^^^^^^^^^^^^^^^^^^^^^^^^^
  File "/home/airflow/.local/lib/python3.11/site-packages/airflow/models/taskinstance.py", line 414, in _execute_callable
    return execute_callable(context=context, **execute_callable_kwargs)
           ^^^^^^^^^^^^^^^^^^^^^^^^^^^^^^^^^^^^^^^^^^^^^^^^^^^^^^^^^^^^
  File "/home/airflow/.local/lib/python3.11/site-packages/airflow/operators/bash.py", line 212, in execute
    raise AirflowException(
airflow.exceptions.AirflowException: Bash command failed. The command returned a non-zero exit code 127.
[2024-03-05T08:01:37.886+0000] {taskinstance.py:1149} INFO - Marking task as UP_FOR_RETRY. dag_id=test_dag, task_id=second_task, execution_date=20240305T080135, start_date=20240305T080137, end_date=20240305T080137
[2024-03-05T08:01:37.893+0000] {standard_task_runner.py:107} ERROR - Failed to execute job 5 for task second_task (Bash command failed. The command returned a non-zero exit code 127.; 852)
[2024-03-05T08:01:37.925+0000] {local_task_job_runner.py:234} INFO - Task exited with return code 1
[2024-03-05T08:01:37.936+0000] {taskinstance.py:3309} INFO - 0 downstream tasks scheduled from follow-on schedule check
