[2024-03-05T11:18:46.945+0000] {taskinstance.py:1979} INFO - Dependencies all met for dep_context=non-requeueable deps ti=<TaskInstance: dag_py_op_v5.greet scheduled__2024-03-04T00:00:00+00:00 [queued]>
[2024-03-05T11:18:46.952+0000] {taskinstance.py:1979} INFO - Dependencies all met for dep_context=requeueable deps ti=<TaskInstance: dag_py_op_v5.greet scheduled__2024-03-04T00:00:00+00:00 [queued]>
[2024-03-05T11:18:46.953+0000] {taskinstance.py:2193} INFO - Starting attempt 1 of 6
[2024-03-05T11:18:46.962+0000] {taskinstance.py:2214} INFO - Executing <Task(PythonOperator): greet> on 2024-03-04 00:00:00+00:00
[2024-03-05T11:18:46.965+0000] {standard_task_runner.py:60} INFO - Started process 2865 to run task
[2024-03-05T11:18:46.968+0000] {standard_task_runner.py:87} INFO - Running: ['***', 'tasks', 'run', 'dag_py_op_v5', 'greet', 'scheduled__2024-03-04T00:00:00+00:00', '--job-id', '40', '--raw', '--subdir', 'DAGS_FOLDER/dag_py_op.py', '--cfg-path', '/tmp/tmp_6577j0r']
[2024-03-05T11:18:46.970+0000] {standard_task_runner.py:88} INFO - Job 40: Subtask greet
[2024-03-05T11:18:47.006+0000] {task_command.py:423} INFO - Running <TaskInstance: dag_py_op_v5.greet scheduled__2024-03-04T00:00:00+00:00 [running]> on host a94d9406bb00
[2024-03-05T11:18:47.217+0000] {taskinstance.py:2510} INFO - Exporting env vars: AIRFLOW_CTX_DAG_OWNER='minh' AIRFLOW_CTX_DAG_ID='dag_py_op_v5' AIRFLOW_CTX_TASK_ID='greet' AIRFLOW_CTX_EXECUTION_DATE='2024-03-04T00:00:00+00:00' AIRFLOW_CTX_TRY_NUMBER='1' AIRFLOW_CTX_DAG_RUN_ID='scheduled__2024-03-04T00:00:00+00:00'
[2024-03-05T11:18:47.218+0000] {taskinstance.py:2728} ERROR - Task failed with exception
Traceback (most recent call last):
  File "/home/airflow/.local/lib/python3.11/site-packages/airflow/models/taskinstance.py", line 444, in _execute_task
    result = _execute_callable(context=context, **execute_callable_kwargs)
             ^^^^^^^^^^^^^^^^^^^^^^^^^^^^^^^^^^^^^^^^^^^^^^^^^^^^^^^^^^^^^
  File "/home/airflow/.local/lib/python3.11/site-packages/airflow/models/taskinstance.py", line 414, in _execute_callable
    return execute_callable(context=context, **execute_callable_kwargs)
           ^^^^^^^^^^^^^^^^^^^^^^^^^^^^^^^^^^^^^^^^^^^^^^^^^^^^^^^^^^^^
  File "/home/airflow/.local/lib/python3.11/site-packages/airflow/operators/python.py", line 200, in execute
    return_value = self.execute_callable()
                   ^^^^^^^^^^^^^^^^^^^^^^^
  File "/home/airflow/.local/lib/python3.11/site-packages/airflow/operators/python.py", line 217, in execute_callable
    return self.python_callable(*self.op_args, **self.op_kwargs)
           ^^^^^^^^^^^^^^^^^^^^^^^^^^^^^^^^^^^^^^^^^^^^^^^^^^^^^
  File "/opt/airflow/dags/dag_py_op.py", line 6, in greet
    name = ti.xcoms_pull(task_ids='get_name')
           ^^^^^^^^^^^^^
AttributeError: 'TaskInstance' object has no attribute 'xcoms_pull'
[2024-03-05T11:18:47.226+0000] {taskinstance.py:1149} INFO - Marking task as UP_FOR_RETRY. dag_id=dag_py_op_v5, task_id=greet, execution_date=20240304T000000, start_date=20240305T111846, end_date=20240305T111847
[2024-03-05T11:18:47.234+0000] {standard_task_runner.py:107} ERROR - Failed to execute job 40 for task greet ('TaskInstance' object has no attribute 'xcoms_pull'; 2865)
[2024-03-05T11:18:47.277+0000] {local_task_job_runner.py:234} INFO - Task exited with return code 1
[2024-03-05T11:18:47.291+0000] {taskinstance.py:3309} INFO - 0 downstream tasks scheduled from follow-on schedule check
